# -*- coding: utf-8 -*-
from django.contrib.auth.models import User
from rest_framework import serializers
from rest_framework.exceptions import ValidationError


class UserSerializer(serializers.Serializer):
    id = serializers.ReadOnlyField()
    username = serializers.CharField()
    first_name = serializers.CharField()
    last_name = serializers.CharField()
    email = serializers.EmailField()
    password = serializers.CharField()

    def create(self, validated_data):
        return self.update(User(), validated_data)

    def update(self, instance, validated_data):
        instance.first_name = validated_data.get('first_name', instance.first_name)
        instance.last_name = validated_data.get('last_name', instance.last_name)
        instance.username = validated_data.get('username', instance.username)
        instance.email = validated_data.get('email', instance.email)
        if validated_data.get('password'):
            instance.set_password(validated_data.get('password'))
        instance.save()
        return instance

    def validate(self, attrs):
        if self.instance is None and User.objects.filter(username=attrs.get("username")).exists():
            raise ValidationError("El nombre de usuario ya existe")

        if self.instance is not None and self.instance.username != attrs.get("username") and User.objects.filter(
                username=attrs.get("username")).exists():
            raise ValidationError("El nombre de usuario ya existe")

        return attrs
